mplus_output/bi-40-SAGE (China)_W1.out
Mplus VERSION 8.1 (Mac)
MUTHEN & MUTHEN
04/23/2020  10:57 PM

INPUT INSTRUCTIONS

  DATA:
  FILE = "bi-40-SAGE (China)_W1.dat";

  VARIABLE:
  NAMES = mplusid UANI UIWR UIWR2 UIWR3 UDIGF UDIGB;
   MISSING=.;
   CATEGORICAL ARE all; idvariable = mplusid;
  ANALYSIS:
  estimator = wlsmv; coverage=0;
  MODEL:
  g by UIWR * ;
   g by UANI * ;
   g by UIWR2 * ;
   g by UIWR3 * ;
   g by UDIGF * ;
   g by UDIGB * ;
   s1 by UIWR * ;
   s1 by UIWR2 * ;
   s1 by UIWR3 * ;
   g @ 1;
   s1 @ 1 ;
   g with s1 @ 0 ;

  OUTPUT:
  standardized; svalues;



INPUT READING TERMINATED NORMALLY




SUMMARY OF ANALYSIS

Number of groups                                                 1
Number of observations                                       14280

Number of dependent variables                                    6
Number of independent variables                                  0
Number of continuous latent variables                            2

Observed dependent variables

  Binary and ordered categorical (ordinal)
   UANI        UIWR        UIWR2       UIWR3       UDIGF       UDIGB

Continuous latent variables
   G           S1

Variables with special functions

  ID variable           MPLUSID

Estimator                                                    WLSMV
Maximum number of iterations                                  1000
Convergence criterion                                    0.500D-04
Maximum number of steepest descent iterations                   20
Maximum number of iterations for H1                           2000
Convergence criterion for H1                             0.100D-03
Parameterization                                             DELTA
Link                                                        PROBIT

Input data file(s)
  bi-40-SAGE (China)_W1.dat

Input data format  FREE


SUMMARY OF DATA

     Number of missing data patterns            12


COVARIANCE COVERAGE OF DATA

Minimum covariance coverage value   0.000


     PROPORTION OF DATA PRESENT


           Covariance Coverage
              UANI          UIWR          UIWR2         UIWR3         UDIGF
              ________      ________      ________      ________      ________
 UANI           0.997
 UIWR           0.996         0.998
 UIWR2          0.996         0.997         0.997
 UIWR3          0.994         0.996         0.996         0.996
 UDIGF          0.997         0.997         0.996         0.995         0.999
 UDIGB          0.994         0.995         0.994         0.993         0.996


           Covariance Coverage
              UDIGB
              ________
 UDIGB          0.996


UNIVARIATE PROPORTIONS AND COUNTS FOR CATEGORICAL VARIABLES

    UANI
      Category 1    0.006           86.000
      Category 2    0.055          788.000
      Category 3    0.225         3198.000
      Category 4    0.336         4785.000
      Category 5    0.216         3067.000
      Category 6    0.110         1566.000
      Category 7    0.040          569.000
      Category 8    0.009          130.000
      Category 9    0.002           31.000
      Category 10    0.001           12.000
    UIWR
      Category 1    0.012          164.000
      Category 2    0.018          252.000
      Category 3    0.069          984.000
      Category 4    0.143         2037.000
      Category 5    0.201         2862.000
      Category 6    0.395         5625.000
      Category 7    0.101         1438.000
      Category 8    0.044          633.000
      Category 9    0.012          178.000
      Category 10    0.005           78.000
    UIWR2
      Category 1    0.006           84.000
      Category 2    0.007          106.000
      Category 3    0.025          351.000
      Category 4    0.063          892.000
      Category 5    0.114         1617.000
      Category 6    0.406         5788.000
      Category 7    0.189         2697.000
      Category 8    0.121         1719.000
      Category 9    0.048          690.000
      Category 10    0.021          297.000
    UIWR3
      Category 1    0.007          102.000
      Category 2    0.005           69.000
      Category 3    0.016          234.000
      Category 4    0.043          607.000
      Category 5    0.076         1079.000
      Category 6    0.308         4380.000
      Category 7    0.203         2891.000
      Category 8    0.166         2361.000
      Category 9    0.107         1523.000
      Category 10    0.069          978.000
    UDIGF
      Category 1    0.004           56.000
      Category 2    0.018          253.000
      Category 3    0.043          615.000
      Category 4    0.103         1471.000
      Category 5    0.155         2212.000
      Category 6    0.217         3093.000
      Category 7    0.243         3469.000
      Category 8    0.217         3099.000
    UDIGB
      Category 1    0.031          446.000
      Category 2    0.178         2528.000
      Category 3    0.341         4851.000
      Category 4    0.238         3380.000
      Category 5    0.109         1548.000
      Category 6    0.058          819.000
      Category 7    0.027          380.000
      Category 8    0.019          265.000



THE MODEL ESTIMATION TERMINATED NORMALLY

     WARNING:  THE RESIDUAL COVARIANCE MATRIX (THETA) IS NOT POSITIVE DEFINITE.
     THIS COULD INDICATE A NEGATIVE VARIANCE/RESIDUAL VARIANCE FOR AN OBSERVED
     VARIABLE, A CORRELATION GREATER OR EQUAL TO ONE BETWEEN TWO OBSERVED
     VARIABLES, OR A LINEAR DEPENDENCY AMONG MORE THAN TWO OBSERVED VARIABLES.
     CHECK THE RESULTS SECTION FOR MORE INFORMATION.
     PROBLEM INVOLVING VARIABLE UIWR2.




MODEL FIT INFORMATION

Number of Free Parameters                       59

Chi-Square Test of Model Fit

          Value                           1261.343*
          Degrees of Freedom                     6
          P-Value                           0.0000

*   The chi-square value for MLM, MLMV, MLR, ULSMV, WLSM and WLSMV cannot be used
    for chi-square difference testing in the regular way.  MLM, MLR and WLSM
    chi-square difference testing is described on the Mplus website.  MLMV, WLSMV,
    and ULSMV difference testing is done using the DIFFTEST option.

RMSEA (Root Mean Square Error Of Approximation)

          Estimate                           0.121
          90 Percent C.I.                    0.115  0.127
          Probability RMSEA <= .05           0.000

CFI/TLI

          CFI                                0.991
          TLI                                0.977

Chi-Square Test of Model Fit for the Baseline Model

          Value                         138265.984
          Degrees of Freedom                    15
          P-Value                           0.0000

SRMR (Standardized Root Mean Square Residual)

          Value                              0.020

Optimum Function Value for Weighted Least-Squares Estimator

          Value                     0.19331103D-01



MODEL RESULTS

                                                    Two-Tailed
                    Estimate       S.E.  Est./S.E.    P-Value

 G        BY
    UIWR               0.623      0.008     82.407      0.000
    UANI               0.563      0.007     80.469      0.000
    UIWR2              0.720      0.007    107.249      0.000
    UIWR3              0.738      0.006    115.772      0.000
    UDIGF              0.650      0.007     97.948      0.000
    UDIGB              0.636      0.007     93.135      0.000

 S1       BY
    UIWR               0.399      0.010     38.629      0.000
    UIWR2              0.743      0.010     77.467      0.000
    UIWR3              0.416      0.010     43.162      0.000

 G        WITH
    S1                 0.000      0.000    999.000    999.000

 Thresholds
    UANI$1            -2.510      0.038    -66.099      0.000
    UANI$2            -1.543      0.017    -93.012      0.000
    UANI$3            -0.565      0.011    -50.707      0.000
    UANI$4             0.312      0.011     29.141      0.000
    UANI$5             0.986      0.013     78.296      0.000
